Traceback (most recent call last):
  File "c:\users\vatsa\appdata\local\programs\python\python37-32\lib\site-packages\jupyter_cache\executors\utils.py", line 56, in single_nb_execution
    record_timing=False,
  File "c:\users\vatsa\appdata\local\programs\python\python37-32\lib\site-packages\nbclient\client.py", line 1082, in execute
    return NotebookClient(nb=nb, resources=resources, km=km, **kwargs).execute()
  File "c:\users\vatsa\appdata\local\programs\python\python37-32\lib\site-packages\nbclient\util.py", line 74, in wrapped
    return just_run(coro(*args, **kwargs))
  File "c:\users\vatsa\appdata\local\programs\python\python37-32\lib\site-packages\nbclient\util.py", line 53, in just_run
    return loop.run_until_complete(coro)
  File "c:\users\vatsa\appdata\local\programs\python\python37-32\lib\asyncio\base_events.py", line 584, in run_until_complete
    return future.result()
  File "c:\users\vatsa\appdata\local\programs\python\python37-32\lib\site-packages\nbclient\client.py", line 536, in async_execute
    cell, index, execution_count=self.code_cells_executed + 1
  File "c:\users\vatsa\appdata\local\programs\python\python37-32\lib\site-packages\nbclient\client.py", line 827, in async_execute_cell
    self._check_raise_for_error(cell, exec_reply)
  File "c:\users\vatsa\appdata\local\programs\python\python37-32\lib\site-packages\nbclient\client.py", line 735, in _check_raise_for_error
    raise CellExecutionError.from_cell_and_msg(cell, exec_reply['content'])
nbclient.exceptions.CellExecutionError: An error occurred while executing the following cell:
------------------
import json,os, math

import subprocess
# from forgi.graph import bulge_graph
# import forgi.visual.mplotlib as fvm

import pandas as pd
import numpy as np
import matplotlib.pyplot as plt
import seaborn as sns
import tensorflow.keras.backend as K
import plotly.express as px
import tensorflow.keras.layers as L
import tensorflow as tf

import warnings
warnings.filterwarnings('ignore')

import tensorflow_addons as tfa

from itertools import combinations_with_replacement
from sklearn.model_selection import train_test_split, KFold,  StratifiedKFold,GroupKFold
from keras.utils import plot_model
from colorama import Fore, Back, Style
------------------

[1;31m---------------------------------------------------------------------------[0m
[1;31mModuleNotFoundError[0m                       Traceback (most recent call last)
[1;32m<ipython-input-2-86f721f41c04>[0m in [0;36m<module>[1;34m[0m
[0;32m      9[0m [1;32mimport[0m [0mmatplotlib[0m[1;33m.[0m[0mpyplot[0m [1;32mas[0m [0mplt[0m[1;33m[0m[1;33m[0m[0m
[0;32m     10[0m [1;32mimport[0m [0mseaborn[0m [1;32mas[0m [0msns[0m[1;33m[0m[1;33m[0m[0m
[1;32m---> 11[1;33m [1;32mimport[0m [0mtensorflow[0m[1;33m.[0m[0mkeras[0m[1;33m.[0m[0mbackend[0m [1;32mas[0m [0mK[0m[1;33m[0m[1;33m[0m[0m
[0m[0;32m     12[0m [1;32mimport[0m [0mplotly[0m[1;33m.[0m[0mexpress[0m [1;32mas[0m [0mpx[0m[1;33m[0m[1;33m[0m[0m
[0;32m     13[0m [1;32mimport[0m [0mtensorflow[0m[1;33m.[0m[0mkeras[0m[1;33m.[0m[0mlayers[0m [1;32mas[0m [0mL[0m[1;33m[0m[1;33m[0m[0m

[1;31mModuleNotFoundError[0m: No module named 'tensorflow'
ModuleNotFoundError: No module named 'tensorflow'

