Traceback (most recent call last):
  File "c:\users\vatsa\appdata\local\programs\python\python37-32\lib\site-packages\jupyter_cache\executors\utils.py", line 56, in single_nb_execution
    record_timing=False,
  File "c:\users\vatsa\appdata\local\programs\python\python37-32\lib\site-packages\nbclient\client.py", line 1082, in execute
    return NotebookClient(nb=nb, resources=resources, km=km, **kwargs).execute()
  File "c:\users\vatsa\appdata\local\programs\python\python37-32\lib\site-packages\nbclient\util.py", line 74, in wrapped
    return just_run(coro(*args, **kwargs))
  File "c:\users\vatsa\appdata\local\programs\python\python37-32\lib\site-packages\nbclient\util.py", line 53, in just_run
    return loop.run_until_complete(coro)
  File "c:\users\vatsa\appdata\local\programs\python\python37-32\lib\asyncio\base_events.py", line 584, in run_until_complete
    return future.result()
  File "c:\users\vatsa\appdata\local\programs\python\python37-32\lib\site-packages\nbclient\client.py", line 536, in async_execute
    cell, index, execution_count=self.code_cells_executed + 1
  File "c:\users\vatsa\appdata\local\programs\python\python37-32\lib\site-packages\nbclient\client.py", line 827, in async_execute_cell
    self._check_raise_for_error(cell, exec_reply)
  File "c:\users\vatsa\appdata\local\programs\python\python37-32\lib\site-packages\nbclient\client.py", line 735, in _check_raise_for_error
    raise CellExecutionError.from_cell_and_msg(cell, exec_reply['content'])
nbclient.exceptions.CellExecutionError: An error occurred while executing the following cell:
------------------
import os, math, random
from collections import Counter

import RNA
import subprocess
from forgi.graph import bulge_graph
import forgi.visual.mplotlib as fvm
from IPython.display import Image, SVG

import numpy as np
import pandas as pd
import seaborn as sns
import matplotlib.pyplot as plt

from colorama import Fore, Back, Style
------------------

[1;31m---------------------------------------------------------------------------[0m
[1;31mModuleNotFoundError[0m                       Traceback (most recent call last)
[1;32m<ipython-input-2-011248e3c1da>[0m in [0;36m<module>[1;34m[0m
[0;32m      2[0m [1;32mfrom[0m [0mcollections[0m [1;32mimport[0m [0mCounter[0m[1;33m[0m[1;33m[0m[0m
[0;32m      3[0m [1;33m[0m[0m
[1;32m----> 4[1;33m [1;32mimport[0m [0mRNA[0m[1;33m[0m[1;33m[0m[0m
[0m[0;32m      5[0m [1;32mimport[0m [0msubprocess[0m[1;33m[0m[1;33m[0m[0m
[0;32m      6[0m [1;32mfrom[0m [0mforgi[0m[1;33m.[0m[0mgraph[0m [1;32mimport[0m [0mbulge_graph[0m[1;33m[0m[1;33m[0m[0m

[1;31mModuleNotFoundError[0m: No module named 'RNA'
ModuleNotFoundError: No module named 'RNA'

