Traceback (most recent call last):
  File "c:\users\mr5\appdata\local\programs\python\python37\lib\site-packages\jupyter_cache\executors\utils.py", line 56, in single_nb_execution
    record_timing=False,
  File "c:\users\mr5\appdata\local\programs\python\python37\lib\site-packages\nbclient\client.py", line 1082, in execute
    return NotebookClient(nb=nb, resources=resources, km=km, **kwargs).execute()
  File "c:\users\mr5\appdata\local\programs\python\python37\lib\site-packages\nbclient\util.py", line 74, in wrapped
    return just_run(coro(*args, **kwargs))
  File "c:\users\mr5\appdata\local\programs\python\python37\lib\site-packages\nbclient\util.py", line 53, in just_run
    return loop.run_until_complete(coro)
  File "c:\users\mr5\appdata\local\programs\python\python37\lib\asyncio\base_events.py", line 579, in run_until_complete
    return future.result()
  File "c:\users\mr5\appdata\local\programs\python\python37\lib\site-packages\nbclient\client.py", line 536, in async_execute
    cell, index, execution_count=self.code_cells_executed + 1
  File "c:\users\mr5\appdata\local\programs\python\python37\lib\site-packages\nbclient\client.py", line 827, in async_execute_cell
    self._check_raise_for_error(cell, exec_reply)
  File "c:\users\mr5\appdata\local\programs\python\python37\lib\site-packages\nbclient\client.py", line 735, in _check_raise_for_error
    raise CellExecutionError.from_cell_and_msg(cell, exec_reply['content'])
nbclient.exceptions.CellExecutionError: An error occurred while executing the following cell:
------------------
import warnings
warnings.filterwarnings('ignore')

import os, gc
import numpy as np
import pandas as pd
from collections import defaultdict,Counter
import random

import matplotlib.pyplot as plt
import seaborn as sns

plt.style.use('fivethirtyeight')

import tensorflow as tf
import tensorflow_addons as tfa
import keras.backend as K
print("Tensorflow version: ",tf.__version__)

# from transformers import *

from sklearn.model_selection import StratifiedKFold, KFold, GroupKFold
from sklearn.metrics import mean_squared_error

from tqdm import tqdm 
import itertools

SEED = 2020

def seed_everything(SEED):
    np.random.seed(SEED)
    tf.random.set_seed(SEED)
    os.environ['PYTHONHASHSEED'] = str(SEED)

seed_everything(SEED)
------------------

[1;31m---------------------------------------------------------------------------[0m
[1;31mModuleNotFoundError[0m                       Traceback (most recent call last)
[1;32m<ipython-input-1-2737a4e9de27>[0m in [0;36m<module>[1;34m[0m
[0;32m     14[0m [1;33m[0m[0m
[0;32m     15[0m [1;32mimport[0m [0mtensorflow[0m [1;32mas[0m [0mtf[0m[1;33m[0m[1;33m[0m[0m
[1;32m---> 16[1;33m [1;32mimport[0m [0mtensorflow_addons[0m [1;32mas[0m [0mtfa[0m[1;33m[0m[1;33m[0m[0m
[0m[0;32m     17[0m [1;32mimport[0m [0mkeras[0m[1;33m.[0m[0mbackend[0m [1;32mas[0m [0mK[0m[1;33m[0m[1;33m[0m[0m
[0;32m     18[0m [0mprint[0m[1;33m([0m[1;34m"Tensorflow version: "[0m[1;33m,[0m[0mtf[0m[1;33m.[0m[0m__version__[0m[1;33m)[0m[1;33m[0m[1;33m[0m[0m

[1;31mModuleNotFoundError[0m: No module named 'tensorflow_addons'
ModuleNotFoundError: No module named 'tensorflow_addons'

